Traceback (most recent call last):
  File "/nas/ucb/tutrinh/selfexplainingai/baselines/llm_baseline.py", line 295, in <module>
    main()
  File "/nas/ucb/tutrinh/selfexplainingai/baselines/llm_baseline.py", line 223, in main
    training_data, validation_data, test_data = get_datasets()
                                                ^^^^^^^^^^^^^^
TypeError: get_datasets() missing 1 required positional argument: 'mismatch'
